INFO:httpx:HTTP Request: GET https://employee-mcp-v1-6b0n96.dw4w1g-2.gbr-e1.cloudhub.io/sse "HTTP/1.1 404 NOT FOUND"
  + Exception Group Traceback (most recent call last):
  |   File "C:\Users\rdamera\AppData\Roaming\Python\Python311\site-packages\IPython\core\interactiveshell.py", line 3672, in run_code
  |     exec(code_obj, self.user_global_ns, self.user_ns)
  |   File "C:\Users\rdamera\AppData\Local\Temp\ipykernel_38988\2043773441.py", line 110, in <module>
  |     asyncio.run(run_agent())
  |   File "C:\Users\rdamera\AppData\Roaming\Python\Python311\site-packages\nest_asyncio.py", line 30, in run
  |     return loop.run_until_complete(task)
  |            ^^^^^^^^^^^^^^^^^^^^^^^^^^^^^
  |   File "C:\Users\rdamera\AppData\Roaming\Python\Python311\site-packages\nest_asyncio.py", line 98, in run_until_complete
  |     return f.result()
  |            ^^^^^^^^^^
  |   File "C:\Program Files\Python311\Lib\asyncio\futures.py", line 203, in result
  |     raise self._exception.with_traceback(self._exception_tb)
  |   File "C:\Program Files\Python311\Lib\asyncio\tasks.py", line 277, in __step
  |     result = coro.send(None)
  |              ^^^^^^^^^^^^^^^
  |   File "C:\Users\rdamera\AppData\Local\Temp\ipykernel_38988\2043773441.py", line 77, in run_agent
  |     async with sse_client(url=url) as streams:
  |   File "C:\Program Files\Python311\Lib\contextlib.py", line 210, in __aenter__
  |     return await anext(self.gen)
  |            ^^^^^^^^^^^^^^^^^^^^^
  |   File "C:\Users\rdamera\AppData\Roaming\Python\Python311\site-packages\mcp\client\sse.py", line 54, in sse_client
  |     async with anyio.create_task_group() as tg:
  |   File "C:\Users\rdamera\AppData\Roaming\Python\Python311\site-packages\anyio\_backends\_asyncio.py", line 772, in __aexit__
  |     raise BaseExceptionGroup(
  | ExceptionGroup: unhandled errors in a TaskGroup (1 sub-exception)
  +-+---------------- 1 ----------------
    | Traceback (most recent call last):
    |   File "C:\Users\rdamera\AppData\Roaming\Python\Python311\site-packages\mcp\client\sse.py", line 64, in sse_client
    |     event_source.response.raise_for_status()
    |   File "C:\Users\rdamera\AppData\Roaming\Python\Python311\site-packages\httpx\_models.py", line 829, in raise_for_status
    |     raise HTTPStatusError(message, request=request, response=self)
    | httpx.HTTPStatusError: Client error '404 NOT FOUND' for url 'https://employee-mcp-v1-6b0n96.dw4w1g-2.gbr-e1.cloudhub.io/sse'
    | For more information check: https://developer.mozilla.org/en-US/docs/Web/HTTP/Status/404
    +------------------------------------
1
