   warnings.warn(
[2025-08-07T11:16:52.863Z] HTTP Request: POST https://testopenaiassets.openai.azure.com/openai/deployments/o4-mini-mulesoft/chat/completions?api-version=2025-04-16 "HTTP/1.1 404 Resource Not Found"
[2025-08-07T11:16:52.865Z] Error during model invocation: Error code: 404 - {'error': {'code': '404', 'message': 'Resource not found'}}
[2025-08-07T11:16:52.873Z] Unhandled error: Error code: 404 - {'error': {'code': '404', 'message': 'Resource not found'}}
Traceback (most recent call last):
  File "C:\Users\rdamera\OneDrive - Capgemini\Desktop\Azure\AZURE_local\Data_Weave_base__V2\Mappingsheet_to_Dataweave_v2\__init__.py", line 153, in main
    result = chat_with_agent(prompt, client)
             ^^^^^^^^^^^^^^^^^^^^^^^^^^^^^^^
  File "C:\Users\rdamera\OneDrive - Capgemini\Desktop\Azure\AZURE_local\Data_Weave_base__V2\Mappingsheet_to_Dataweave_v2\__init__.py", line 100, in chat_with_agent
    result = client.invoke(messages)
             ^^^^^^^^^^^^^^^^^^^^^^^
  File "C:\Users\rdamera\Downloads\my-function-app\.venv\Lib\site-packages\langchain_core\language_models\chat_models.py", line 372, in invoke
    self.generate_prompt(
  File "C:\Users\rdamera\Downloads\my-function-app\.venv\Lib\site-packages\langchain_core\language_models\chat_models.py", line 957, in generate_prompt
    return self.generate(prompt_messages, stop=stop, callbacks=callbacks, **kwargs)
           ^^^^^^^^^^^^^^^^^^^^^^^^^^^^^^^^^^^^^^^^^^^^^^^^^^^^^^^^^^^^^^^^^^^^^^^^
  File "C:\Users\rdamera\Downloads\my-function-app\.venv\Lib\site-packages\langchain_core\language_models\chat_models.py", line 776, in generate
    self._generate_with_cache(
  File "C:\Users\rdamera\Downloads\my-function-app\.venv\Lib\site-packages\langchain_core\language_models\chat_models.py", line 1022, in _generate_with_cache
    result = self._generate(
             ^^^^^^^^^^^^^^^
  File "C:\Users\rdamera\Downloads\my-function-app\.venv\Lib\site-packages\langchain_community\chat_models\openai.py", line 476, in _generate
    response = self.completion_with_retry(
               ^^^^^^^^^^^^^^^^^^^^^^^^^^^
  File "C:\Users\rdamera\Downloads\my-function-app\.venv\Lib\site-packages\langchain_community\chat_models\openai.py", line 387, in completion_with_retry
    return self.client.create(**kwargs)
           ^^^^^^^^^^^^^^^^^^^^^^^^^^^^
  File "C:\Users\rdamera\Downloads\my-function-app\.venv\Lib\site-packages\openai\_utils\_utils.py", line 287, in wrapper
    return func(*args, **kwargs)
           ^^^^^^^^^^^^^^^^^^^^^
  File "C:\Users\rdamera\Downloads\my-function-app\.venv\Lib\site-packages\openai\resources\chat\completions\completions.py", line 925, in create
    return self._post(
           ^^^^^^^^^^^
  File "C:\Users\rdamera\Downloads\my-function-app\.venv\Lib\site-packages\openai\_base_client.py", line 1242, in post
    return cast(ResponseT, self.request(cast_to, opts, stream=stream, stream_cls=stream_cls))
                           ^^^^^^^^^^^^^^^^^^^^^^^^^^^^^^^^^^^^^^^^^^^^^^^^^^^^^^^^^^^^^^^^^
  File "C:\Users\rdamera\Downloads\my-function-app\.venv\Lib\site-packages\openai\_base_client.py", line 1037, in request
    raise self._make_status_error_from_response(err.response) from None
openai.NotFoundError: Error code: 404 - {'error': {'code': '404', 'message': 'Resource not found'}}
[2025-08-07T11:16:52.936Z] Executed 'Functions.Mappingsheet_to_Dataweave_v2' (Succeeded, Id=004a3644-b58f-4992-80a5-9c7ea8a887ed, Duration=4921ms)
[2025-08-07T11:16:52.958Z] Executed HTTP request: {
[2025-08-07T11:16:52.959Z]   "requestId": "da4a8dfe-2a5a-4b3a-b8c1-0b99f21ef108",
[2025-08-07T11:16:52.960Z]   "identities": "(WebJobsAuthLevel:Admin)",
[2025-08-07T11:16:52.961Z]   "status": "500",
[2025-08-07T11:16:52.962Z]   "duration": "5149"
