=== MCP Auto-fetch Agent ===
  + Exception Group Traceback (most recent call last):
  |   File "C:\Users\rdamera\AppData\Roaming\Python\Python311\site-packages\IPython\core\interactiveshell.py", line 3672, in run_code
  |     exec(code_obj, self.user_global_ns, self.user_ns)
  |   File "C:\Users\rdamera\AppData\Local\Temp\ipykernel_13612\1727145661.py", line 83, in <module>
  |     agent = build_agent()
  |             ^^^^^^^^^^^^^
  |   File "C:\Users\rdamera\AppData\Local\Temp\ipykernel_13612\1727145661.py", line 68, in build_agent
  |     tools = get_tools()
  |             ^^^^^^^^^^^
  |   File "C:\Users\rdamera\AppData\Local\Temp\ipykernel_13612\1727145661.py", line 36, in get_tools
  |     info = sync_call_tool("list_tools", {})
  |            ^^^^^^^^^^^^^^^^^^^^^^^^^^^^^^^^
  |   File "C:\Users\rdamera\AppData\Local\Temp\ipykernel_13612\1727145661.py", line 32, in sync_call_tool
  |     return asyncio.get_event_loop().run_until_complete(call())
  |            ^^^^^^^^^^^^^^^^^^^^^^^^^^^^^^^^^^^^^^^^^^^^^^^^^^^
  |   File "C:\Users\rdamera\AppData\Roaming\Python\Python311\site-packages\nest_asyncio.py", line 98, in run_until_complete
  |     return f.result()
  |            ^^^^^^^^^^
  |   File "C:\Program Files\Python311\Lib\asyncio\futures.py", line 203, in result
  |     raise self._exception.with_traceback(self._exception_tb)
  |   File "C:\Program Files\Python311\Lib\asyncio\tasks.py", line 279, in __step
  |     result = coro.throw(exc)
  |              ^^^^^^^^^^^^^^^
  |   File "C:\Users\rdamera\AppData\Local\Temp\ipykernel_13612\1727145661.py", line 28, in call
  |     async with sse_client(url=sse_url) as streams:
  |   File "C:\Program Files\Python311\Lib\contextlib.py", line 231, in __aexit__
  |     await self.gen.athrow(typ, value, traceback)
  |   File "C:\Users\rdamera\AppData\Roaming\Python\Python311\site-packages\mcp\client\sse.py", line 54, in sse_client
  |     async with anyio.create_task_group() as tg:
  |   File "C:\Users\rdamera\AppData\Roaming\Python\Python311\site-packages\anyio\_backends\_asyncio.py", line 772, in __aexit__
  |     raise BaseExceptionGroup(
  | ExceptionGroup: unhandled errors in a TaskGroup (1 sub-exception)
  +-+---------------- 1 ----------------
    | Exception Group Traceback (most recent call last):
    |   File "C:\Users\rdamera\AppData\Roaming\Python\Python311\site-packages\mcp\client\sse.py", line 138, in sse_client
    |     yield read_stream, write_stream
    |   File "C:\Users\rdamera\AppData\Local\Temp\ipykernel_13612\1727145661.py", line 29, in call
    |     async with ClientSession(*streams) as session:
    |   File "C:\Users\rdamera\AppData\Roaming\Python\Python311\site-packages\anyio\_backends\_asyncio.py", line 772, in __aexit__
    |     raise BaseExceptionGroup(
    | ExceptionGroup: unhandled errors in a TaskGroup (1 sub-exception)
    +-+---------------- 1 ----------------
      | Traceback (most recent call last):
      |   File "C:\Users\rdamera\AppData\Local\Temp\ipykernel_13612\1727145661.py", line 31, in call
      |     return await session.call_tool(name, params)
      |            ^^^^^^^^^^^^^^^^^^^^^^^^^^^^^^^^^^^^^
      |   File "C:\Users\rdamera\AppData\Roaming\Python\Python311\site-packages\mcp\client\session.py", line 264, in call_tool
      |     return await self.send_request(
      |            ^^^^^^^^^^^^^^^^^^^^^^^^
      |   File "C:\Users\rdamera\AppData\Roaming\Python\Python311\site-packages\mcp\shared\session.py", line 286, in send_request
      |     raise McpError(response_or_error.error)
      | mcp.shared.exceptions.McpError: Tool not found: list_tools
      +------------------------------------
